[33mWARNING [0m urllib3.connectionpool:connectionpool.py:868 Retrying (Retry(total=2, connect=None, read=None, redirect=None, status=None)) after connection broken by 'NameResolutionError("<urllib3.connection.HTTPConnection object at 0x0000018556DA4650>: Failed to resolve 'selenium' ([Errno 11001] getaddrinfo failed)")': /session
[33mWARNING [0m urllib3.connectionpool:connectionpool.py:868 Retrying (Retry(total=1, connect=None, read=None, redirect=None, status=None)) after connection broken by 'NameResolutionError("<urllib3.connection.HTTPConnection object at 0x0000018556DA4790>: Failed to resolve 'selenium' ([Errno 11001] getaddrinfo failed)")': /session
[33mWARNING [0m urllib3.connectionpool:connectionpool.py:868 Retrying (Retry(total=0, connect=None, read=None, redirect=None, status=None)) after connection broken by 'NameResolutionError("<urllib3.connection.HTTPConnection object at 0x0000018556DA7DD0>: Failed to resolve 'selenium' ([Errno 11001] getaddrinfo failed)")': /session